Workbook

Sheet переходы
A1: Cu1
B2: BHandHLYP | E2: CAM-B3LYP | H2: M06-2X | K2: PBE0 | N2: wB97X | Q2: DLPNO-STEOM-CCSD
A3: № | B3: Переход | C3: wavelength, nm | D3: f_osc | E3: Переход | F3: wavelength, nm | G3: f_osc | H3: Переход | I3: wavelength, nm | J3: f_osc | K3: Переход | L3: wavelength, nm | M3: f_osc | N3: Переход | O3: wavelength, nm | P3: f_osc | Q3: Переход | R3: wavelength, nm | S3: f_osc
A4: 1 | B4: 39 -> 40 | C4: 262.5 | D4: 0.010366469 | E4: 39 -> 40 | F4: 273.9 | G4: 0.008684514 | H4: 39 -> 40 | I4: 271.5 | J4: 0.014450027 | K4: 39 -> 40 | L4: 289.9 | M4: 0.008078613 | N4: 39 -> 40 | O4: 253 | P4: 0.009221796 | Q4: 39 -> 40 | R4: 285.5 | S4: 1e-09
A5: 2 | B5: 38 -> 40 | C5: 259.1 | D5: 0.015053549 | E5: 38 -> 40 | F5: 269.8 | G5: 0.012783742 | H5: 38 -> 40 | I5: 267.6 | J5: 0.020117917 | K5: 38 -> 40 | L5: 284.4 | M5: 0.017645107 | N5: 38 -> 40 | O5: 249.8 | P5: 0.010543971 | Q5: 38 -> 40 | R5: 279.7 | S5: 1.5e-08
A6: 3 | B6: 38 -> 42 39 -> 42 | C6: 238.6 | D6: 0.014910393 | E6: 38 -> 42 | F6: 248.8 | G6: 0.011577237 | H6: 38 -> 42 | I6: 246.5 | J6: 0.011328634 | K6: 39 -> 41 | L6: 257.7 | M6: 0.016960046 | N6: 39 -> 42 | O6: 237.6 | P6: 0.008568402 | Q6: 36 -> 40 | R6: 279.5 | S6: 6e-09
A7: 4 | B7: 38 -> 42 39 -> 42 | C7: 238.2 | D7: 0.014560598 | E7: 39 -> 42 | F7: 248.4 | G7: 0.010630932 | H7: 39 -> 42 | I7: 245.9 | J7: 0.007550445 | K7: 38 -> 41 39 -> 42 | L7: 257.1 | M7: 0.007968171 | N7: 38 -> 42 39 -> 42 | O7: 237.2 | P7: 0.009704584 | Q7: 39 -> 40 | R7: 277.9 | S7: 0.008483392
A8: 5 | B8: 37 -> 40 | C8: 229.2 | D8: 0.002059979 | E8: 37 -> 40 | F8: 235.2 | G8: 0.001525423 | H8: 37 -> 40 | I8: 235.5 | J8: 0.000881624 | K8: 37 -> 40 | L8: 251.7 | M8: 0.004704837 | N8: 37 -> 40 | O8: 220.6 | P8: 0.000651859 | Q8: 38 -> 40 | R8: 273 | S8: 0.012526676
A9: 6 | B9: 36 -> 40 | C9: 221 | D9: 0.061051567 | E9: 36 -> 40 | F9: 224.3 | G9: 0.036440266 | H9: 36 -> 40 | I9: 229.9 | J9: 0.083050665 | K9: 36 -> 40 | L9: 239 | M9: 0.015951298 | N9: 36 -> 40 | O9: 207.4 | P9: 0.044245119 | Q9: 39 -> 42 | R9: 262.4 | S9: 4.25e-07
A10: 7 | B10: 38 -> 41 | C10: 209.5 | D10: 0.003620906 | E10: 38 -> 41 | F10: 217.7 | G10: 0.001214996 | H10: 36 -> 41 37 -> 42 | I10: 214.1 | J10: 0.001867358 | K10: 38 -> 41 | L10: 238.5 | M10: 0.000350156 | N10: 37 -> 42 | O10: 206.1 | P10: 0.004902459 | Q10: 39 -> 41 | R10: 262 | S10: 5.73e-07
A11: 8 | B11: 36 -> 42 37 -> 41 | C11: 208.7 | D11: 0.007352231 | E11: 37 -> 41 38 -> 42 39 -> 41 | F11: 216.2 | G11: 0.060002925 | H11: 36 -> 42 | I11: 213.2 | J11: 0.001162181 | K11: 36 -> 40 | L11: 232.1 | M11: 0.12703921 | N11: 36 -> 40 36 -> 42 38 -> 42 39 -> 41 | O11: 204.5 | P11: 0.021539246 | Q11: 36 -> 40 | R11: 249.6 | S11: 0.007277629
A12: 9 | B12: 37 -> 42 | C12: 203.8 | D12: 0.001986997 | E12: 37 -> 42 | F12: 211.5 | G12: 0.011042985 | H12: 38 -> 41 | I12: 205.1 | J12: 0.000441309 | K12: 37 -> 41 | L12: 225.1 | M12: 0.11728935 | N12: 34 -> 40 | O12: 202.6 | P12: 0.000762864 | Q12: 36 -> 40 38 -> 42 39 -> 41 | R12: 249.3 | S12: 0.008653048
A13: 10 | B13: 38 -> 42 39 -> 41 | C13: 200.5 | D13: 0.3017402 | E13: 35 -> 40 | F13: 209.8 | G13: 0.001390237 | H13: 38 -> 42 39 -> 41 | I13: 202.3 | J13: 0.30617617 | K13: 37 -> 42 | L13: 222.3 | M13: 0.018253425 | N13: 35 -> 40 | O13: 202.5 | P13: 0.003121764 | Q13: 36 -> 40 | R13: 248.5 | S13: 0.007752046
A14: 11 | B14: 36 -> 41 36 -> 42 | C14: 191.5 | D14: 0.034762589 | E14: 34 -> 40 | F14: 209.8 | G14: 0.000351308 | H14: 37 -> 41 | I14: 192.5 | J14: 0.018567414 | K14: 35 -> 40 | L14: 218.8 | M14: 0.000465084 | N14: 35 -> 40 37 -> 42 | O14: 202.3 | P14: 0.007351696
A15: 12 | B15: 36 -> 41 36 -> 42 | C15: 191.4 | D15: 0.034400712 | E15: 37 -> 41 | F15: 207.5 | G15: 0.26736854 | H15: 36 -> 41 37 -> 42 | I15: 191.9 | J15: 0.012238278 | K15: 34 -> 40 | L15: 218.7 | M15: 0.000699747 | N15: 36 -> 40 38 -> 42 | O15: 195.2 | P15: 0.34370699
A16: 13 | B16: 34 -> 40 | C16: 188.7 | D16: 0.000225513 | E16: 36 -> 42 | F16: 198.4 | G16: 0.053049288 | I16: 190.1 | J16: 0.004202447 | K16: 36 -> 41 | L16: 212.3 | M16: 0.007211061 | O16: 190.2 | P16: 0.039108734
A17: 14 | B17: 33 -> 40 | C17: 188.7 | D17: 0.00010988 | E17: 36 -> 41 | F17: 198.2 | G17: 0.017423655 | I17: 189.8 | J17: 0.003174896 | K17: 36 -> 42 | L17: 209.1 | M17: 0.090273762 | O17: 188.3 | P17: 0.007959236
A18: 15 | B18: 35 -> 40 | C18: 183.7 | D18: 0.014326325 | E18: 33 -> 40 | F18: 195.5 | G18: 0.011592155 | I18: 188.3 | J18: 0.013274399 | K18: 33 -> 40 | L18: 203.1 | M18: 0.008998243 | O18: 187.7 | P18: 0.017982891
A19: 16 | B19: 32 -> 40 | C19: 183.4 | D19: 0.009441859 | E19: 32 -> 40 | F19: 195.1 | G19: 0.04389254 | I19: 188.2 | J19: 0.016806766 | K19: 32 -> 40 | L19: 202.9 | M19: 0.011190517 | O19: 187 | P19: 0.018147074
A20: 17 | B20: 38 -> 46 39 -> 43 | C20: 176.7 | D20: 0.000194786 | E20: 35 -> 42 | F20: 190.4 | G20: 0.00236706 | I20: 181.5 | J20: 0.000262388 | K20: 35 -> 42 | L20: 199 | M20: 0.001027282 | O20: 186.6 | P20: 0.001367739
A21: 18 | B21: 38 -> 43 39 -> 46 | C21: 176.4 | D21: 0.011464489 | E21: 34 -> 42 | F21: 190.4 | G21: 0.000265317 | I21: 181.2 | J21: 0.005951911 | K21: 34 -> 42 | L21: 198.9 | M21: 7.0681e-05 | O21: 186.1 | P21: 0.12775989
A22: 19 | B22: 39 -> 44 | C22: 171.3 | D22: 0.010788504 | E22: 39 -> 43 | F22: 185 | G22: 0.001101765 | I22: 172.6 | J22: 0.006404353 | K22: 34 -> 41 | L22: 195 | M22: 0.005705316 | O22: 181.1 | P22: 0.002615442
A23: 20 | B23: 38 -> 44 | C23: 169.8 | D23: 0.033628854 | E23: 34 -> 41 | F23: 184.6 | G23: 0.017548186 | I23: 171.6 | J23: 0.01995137 | K23: 35 -> 41 | L23: 194.7 | M23: 0.005498449 | O23: 180.6 | P23: 0.019519245
A26: Cu2
B27: BHandHLYP | E27: CAM-B3LYP | H27: M06-2X | K27: PBE0 | N27: wB97X | Q27: DLPNO-STEOM-CCSD
A28: № | B28: Переход | C28: wavelength, nm | D28: f_osc | E28: Переход | F28: wavelength, nm | G28: f_osc | H28: Переход | I28: wavelength, nm | J28: f_osc | K28: Переход | L28: wavelength, nm | M28: f_osc | N28: Переход | O28: wavelength, nm | P28: f_osc | Q28: Переход | R28: wavelength, nm | S28: f_osc
A29: 1 | B29: 54 -> 55 | C29: 388.4 | D29: 0.25775201 | E29: 54 -> 55 | F29: 367.5 | G29: 0.22457532 | H29: 54 -> 55 | I29: 396.1 | J29: 0.40747682 | K29: 54 -> 55 | L29: 416.8 | M29: 0.15726677 | N29: 54 -> 55 | O29: 327.6 | P29: 0.49411373 | Q29: 54 -> 57 | R29: 425.4 | S29: 1.1667e-05
A30: 2 | B30: 54 -> 56 | C30: 373.3 | D30: 0.027604323 | E30: 54 -> 56 | F30: 354.9 | G30: 0.022313331 | H30: 54 -> 56 | I30: 373.4 | J30: 0.034535331 | K30: 54 -> 56 | L30: 404.3 | M30: 0.019064068 | N30: 54 -> 57 | O30: 317.5 | P30: 0.070116562 | Q30: 54 -> 56 | R30: 399.3 | S30: 1.466e-06
A31: 3 | B31: 54 -> 57 | C31: 340 | D31: 0.36075038 | E31: 54 -> 57 | F31: 332.9 | G31: 0.29522304 | H31: 54 -> 57 | I31: 365.3 | J31: 0.23288551 | K31: 54 -> 57 | L31: 348.8 | M31: 0.32676563 | N31: 54 -> 56 | O31: 308.4 | P31: 0.030294721 | Q31: 54 -> 55 | R31: 383.2 | S31: 2e-08
A32: 4 | B32: 54 -> 58 | C32: 281.1 | D32: 0.025334146 | E32: 53 -> 55 | F32: 298.5 | G32: 3.1936e-05 | H32: 54 -> 58 | I32: 292.5 | J32: 0.035419268 | K32: 53 -> 55 | L32: 322.1 | M32: 4.5709e-05 | N32: 54 -> 58 | O32: 279.1 | P32: 0.006804709 | Q32: 54 -> 55 | R32: 369.6 | S32: 0.44451222
A33: 5 | B33: 53 -> 55 | C33: 275.8 | D33: 8.0421e-05 | E33: 51 -> 55 53 -> 56 | F33: 297.7 | G33: 2.3042e-05 | H33: 52 -> 56 53 -> 55 | I33: 275.2 | J33: 0.008820891 | K33: 51 -> 55 | L33: 320.1 | M33: 1.1862e-05 | N33: 54 -> 58 | O33: 278.7 | P33: 0.003469848 | Q33: 54 -> 56 | R33: 348.2 | S33: 0.043827317
A34: 6 | B34: 52 -> 55 53 -> 56 | C34: 275.4 | D34: 0.000194179 | E34: 54 -> 58 | F34: 285 | G34: 0.006651221 | H34: 52 -> 55 53 -> 56 | I34: 275 | J34: 0.018655398 | K34: 52 -> 55 53 -> 55 | L34: 311.9 | M34: 0.002395357 | N34: 51 -> 57 53 -> 56 | O34: 277.8 | P34: 0.001269438 | Q34: 54 -> 58 | R34: 340.4 | S34: 1.75e-07
A35: 7 | B35: 54 -> 59 | C35: 257.5 | D35: 0.045451587 | E35: 52 -> 55 | F35: 276.5 | G35: 0.020541575 | H35: 54 -> 59 | I35: 272.5 | J35: 0.052008884 | K35: 53 -> 56 | L35: 305.3 | M35: 0.016846748 | N35: 52 -> 57 | O35: 263 | P35: 0.028225286 | Q35: 54 -> 57 | R35: 334.7 | S35: 0.30871503
A36: 8 | B36: 54 -> 60 | C36: 256.8 | D36: 0.10185636 | E36: 52 -> 56 | F36: 273.4 | G36: 0.022586829 | H36: 54 -> 60 | I36: 272.1 | J36: 0.091926844 | K36: 54 -> 58 | L36: 296.1 | M36: 0.011276842 | N36: 53 -> 55 53 -> 57 | O36: 259.5 | P36: 0.003597721 | Q36: 54 -> 59 | R36: 287.8 | S36: 3.67e-07
A37: 9 | B37: 51 -> 55 | C37: 253.8 | D37: 0.022576138 | E37: 53 -> 57 | F37: 269.4 | G37: 0.006947034 | H37: 53 -> 57 | I37: 249.7 | J37: 0.042185423 | K37: 51 -> 55 | L37: 290.3 | M37: 0.046579103 | N37: 52 -> 56 | O37: 257 | P37: 0.029520598 | Q37: 54 -> 58 | R37: 275.7 | S37: 0.028367392
A38: 10 | B38: 51 -> 56 | C38: 251.4 | D38: 0.030850996 | E38: 51 -> 57 | F38: 264.3 | G38: 0.005872936 | H38: 51 -> 55 | I38: 248.2 | J38: 0.007127692 | K38: 51 -> 56 | L38: 289.9 | M38: 0.013678377 | N38: 51 -> 55 51 -> 57 | O38: 254.3 | P38: 0.025213781 | Q38: 54 -> 59 | R38: 255.3 | S38: 0.006322222
A39: 11 | B39: 53 -> 57 | C39: 242.9 | D39: 0.029728209 | E39: 52 -> 57 | F39: 261.1 | G39: 0.013300068 | H39: 52 -> 57 | I39: 248 | J39: 0.033440879 | K39: 52 -> 57 | L39: 284.3 | M39: 0.00731109 | N39: 54 -> 59 | O39: 249.6 | P39: 0.00636552
A40: 12 | B40: 52 -> 57 | C40: 240.3 | D40: 0.021635956 | E40: 54 -> 59 | F40: 258.5 | G40: 0.017703755 | H40: 51 -> 56 | I40: 245.9 | J40: 0.015292715 | K40: 51 -> 57 | L40: 277.9 | M40: 0.025406223 | N40: 54 -> 59 | O40: 248.6 | P40: 0.000698894
A43: Cu3
B44: BHandHLYP | E44: CAM-B3LYP | H44: M06-2X | K44: PBE0 | N44: wB97X | Q44: DLPNO-STEOM-CCSD
...

Sheet разность
A1: Разность переходов (CCSD – функционал)^2 в эВ | J1: Средне-квадратичная разность переходов 'CCSD – функционал' в эВ
A2: (красным выделены переходы, которые не были учтены) | J2: BHandHLYP | K2: CAM-B3LYP | L2: M06-2X | M2: PBE0 | N2: wB97X
A3: Cu1 | J3: =sqrt(sum(B8:B10,B12,B22:B23,B25,B27:B28,B34,B42,B44:B46,B53,B55:B57)) -> 1.6599522 | K3: =sqrt(sum(C8:C10,C12,C22:C23,C25,C27:C28,C34,C42,C44:C46,C53,C55:C57)) -> 1.0483571 | L3: =sqrt(sum(D8:D10,D12,D22:D23,D25,D27:D28,D34,D42,D44:D46,D53,D55:D57)) -> 1.3928077 | M3: =sqrt(sum(E8:E10,E12,E22:E23,E25,E27:E28,E34,E42,E44:E46,E53,E55:E57)) -> 1.4178364 | N3: =sqrt(sum(F8:F10,F12,F22:F23,F25,F27:F28,F34,F42,F44:F46,F53,F55:F57)) -> 1.7542434
A4: Переход | B4: BHandHLYP | C4: CAM-B3LYP | D4: M06-2X | E4: PBE0 | F4: wB97X | G4: CCSD: f_osc
A5: 39 -> 40 | B5: =('переходы'!$R4-'переходы'!C4)^2 -> 529 | C5: =('переходы'!$R4-'переходы'!F4)^2 -> 134.56 | D5: =('переходы'!$R4-'переходы'!I4)^2 -> 196 | E5: =('переходы'!$R4-'переходы'!L4)^2 -> 19.36 | F5: =('переходы'!$R4-'переходы'!O4)^2 -> 1056.25 | G5: 1e-09 | J5: Средне-квадратичная разность переходов HOMO->LUMO 'CCSD – функционал' в эВ
A6: 38 -> 40 | B6: =('переходы'!$R5-'переходы'!C5)^2 -> 424.36 | C6: =('переходы'!$R5-'переходы'!F5)^2 -> 98.01 | D6: =('переходы'!$R5-'переходы'!I5)^2 -> 146.41 | E6: =('переходы'!$R5-'переходы'!L5)^2 -> 22.09 | F6: =('переходы'!$R5-'переходы'!O5)^2 -> 894.01 | G6: 1.5e-08 | J6: BHandHLYP | K6: CAM-B3LYP | L6: M06-2X | M6: PBE0 | N6: wB97X
A7: 36 -> 40 | B7: =('переходы'!$R6-'переходы'!C9)^2 -> 3422.25 | C7: =('переходы'!$R6-'переходы'!F9)^2 -> 3047.04 | D7: =('переходы'!$R6-'переходы'!I9)^2 -> 2460.16 | E7: =('переходы'!$R6-'переходы'!L9)^2 -> 1640.25 | F7: =('переходы'!$R6-'переходы'!O9)^2 -> 5198.41 | G7: 6e-09 | J7: =sqrt(sum(B8,B22,B34,B42,B53)) -> 0.44824167 | K7: =sqrt(sum(C8,C22,C34,C42,C53)) -> 0.37307338 | L7: =sqrt(sum(D8,D22,D34,D42,D53)) -> 0.47954868 | M7: =sqrt(sum(E8,E22,E34,E42,E53)) -> 0.68275829 | N7: =sqrt(sum(F8,F22,F34,F42,F53)) -> 0.78862461
A8: 39 -> 40 | B8: =(1240/'переходы'!$R7-1240/'переходы'!C4)^2 -> 0.068525009 | C8: =(1240/'переходы'!$R7-1240/'переходы'!F4)^2 -> 0.0042462171 | D8: =(1240/'переходы'!$R7-1240/'переходы'!I4)^2 -> 0.011063348 | E8: =(1240/'переходы'!$R7-1240/'переходы'!L4)^2 -> 0.034113976 | F8: =(1240/'переходы'!$R7-1240/'переходы'!O4)^2 -> 0.1928519 | G8: 0.008483392
A9: 38 -> 40 | B9: =(1240/'переходы'!$R8-1240/'переходы'!C5)^2 -> 0.059376262 | C9: =(1240/'переходы'!$R8-1240/'переходы'!F5)^2 -> 0.0029022455 | D9: =(1240/'переходы'!$R8-1240/'переходы'!I5)^2 -> 0.0084010463 | E9: =(1240/'переходы'!$R8-1240/'переходы'!L5)^2 -> 0.03314886 | F9: =(1240/'переходы'!$R8-1240/'переходы'!O5)^2 -> 0.17795458 | G9: 0.012526676
A10: 39 -> 42 | B10: =(1240/'переходы'!$R9-1240/'переходы'!C7)^2 -> 0.23049575 | C10: =(1240/'переходы'!$R9-1240/'переходы'!F7)^2 -> 0.070936311 | D10: =(1240/'переходы'!$R9-1240/'переходы'!I7)^2 -> 0.1005464 | E10: =(1240/'переходы'!$R9-1240/'переходы'!L7)^2 -> 0.0094899362 | F10: =(1240/'переходы'!$R9-1240/'переходы'!O7)^2 -> 0.25205042 | G10: 4.25e-07 | I10: Квадрат разности энергии соответствующих переходов 'CCSD – функционал' в эВ
A11: 39 -> 41 | B11: =('переходы'!$R10)^2 -> 68644 | C11: =('переходы'!$R10)^2 -> 68644 | D11: =('переходы'!$R10)^2 -> 68644 | E11: =('переходы'!$R10)^2 -> 68644 | F11: =('переходы'!$R10)^2 -> 68644 | G11: 5.73e-07 | I11: переход | J11: BHandHLYP | K11: CAM-B3LYP | L11: M06-2X | M11: PBE0 | N11: wB97X
A12: 36 -> 40 | B12: =(1240/'переходы'!$R11-1240/'переходы'!C9)^2 -> 0.41333457 | C12: =(1240/'переходы'!$R11-1240/'переходы'!F9)^2 -> 0.3140051 | D12: =(1240/'переходы'!$R11-1240/'переходы'!I9)^2 -> 0.18122108 | E12: =(1240/'переходы'!$R11-1240/'переходы'!L9)^2 -> 0.048547865 | F12: =(1240/'переходы'!$R11-1240/'переходы'!O9)^2 -> 1.0217899 | G12: 0.007277629 | I12: Cu[SCH3]2
A13: 36 -> 40, 38 -> 42, 39 -> 41 | B13: =('переходы'!$R12-'переходы'!C13)^2 -> 2381.44 | C13: =('переходы'!$R12-'переходы'!F11)^2 -> 1095.61 | D13: =('переходы'!$R12-'переходы'!I13)^2 -> 2209 | E13: =('переходы'!$R12-'переходы'!L11)^2 -> 295.84 | F13: =('переходы'!$R12-'переходы'!O11)^2 -> 2007.04 | G13: 0.008653048 | I13: =I39 -> HOMO -> LUMO | J13: =B8 -> 0.068525009 | K13: =C8 -> 0.0042462171 | L13: =D8 -> 0.011063348 | M13: =E8 -> 0.034113976 | N13: =F8 -> 0.1928519
A14: 36 -> 40 | B14: =('переходы'!$R13)^2 -> 61752.25 | C14: =('переходы'!$R13)^2 -> 61752.25 | D14: =('переходы'!$R13)^2 -> 61752.25 | E14: =('переходы'!$R13)^2 -> 61752.25 | F14: =('переходы'!$R13)^2 -> 61752.25 | G14: 0.007752046 | I14: =I40 -> HOMO-1 -> LUMO | J14: =B9 -> 0.059376262 | K14: =C9 -> 0.0029022455 | L14: =D9 -> 0.0084010463 | M14: =E9 -> 0.03314886 | N14: =F9 -> 0.17795458
I15: =I41 -> HOMO -> LUMO+2 | J15: =B10 -> 0.23049575 | K15: =C10 -> 0.070936311 | L15: =D10 -> 0.1005464 | M15: =E10 -> 0.0094899362 | N15: =F10 -> 0.25205042
I16: =I42 -> HOMO-3 -> LUMO | J16: =B12 -> 0.41333457 | K16: =C12 -> 0.3140051 | L16: =D12 -> 0.18122108 | M16: =E12 -> 0.048547865 | N16: =F12 -> 1.0217899
A17: Cu2 | I17: Cu2[SCH3]2
A18: Переход | B18: BHandHLYP | C18: CAM-B3LYP | D18: M06-2X | E18: PBE0 | F18: wB97X | G18: CCSD: f_osc | I18: =I44 -> HOMO -> LUMO | J18: =B22 -> 0.026371613 | K18: =C22 -> 0.00036753893 | L18: =D22 -> 0.050380388 | M18: =E22 -> 0.14434709 | N18: =F22 -> 0.18500789
A19: 54 -> 57 | B19: =('переходы'!$R29-'переходы'!C31)^2 -> 7293.16 | C19: =('переходы'!$R29)^2 -> 180965.16 | D19: =('переходы'!$R29)^2 -> 180965.16 | E19: =('переходы'!$R29)^2 -> 180965.16 | F19: =('переходы'!$R29)^2 -> 180965.16 | G19: 1.1667e-05 | I19: =I45 -> HOMO -> LUMO+1 | J19: =B23 -> 0.0073765911 | K19: =C23 -> 0.004519844 | L19: =D23 -> 0.057761477 | M19: =E23 -> 0.24417662 | N19: =F23 -> 0.21121426
A20: 54 -> 56 | B20: =('переходы'!$R30-'переходы'!C30)^2 -> 676 | C20: =('переходы'!$R30)^2 -> 159440.49 | D20: =('переходы'!$R30)^2 -> 159440.49 | E20: =('переходы'!$R30)^2 -> 159440.49 | F20: =('переходы'!$R30)^2 -> 159440.49 | G20: 1.466e-06 | I20: =I46 -> HOMO -> LUMO+2 | J20: =B25 -> 0.0033352305 | K20: =C25 -> 0.00040128171 | L20: =D25 -> 0.096310903 | M20: =E25 -> 0.022429377 | N20: =F25 -> 0.040281105
A21: 54 -> 55 | B21: =('переходы'!$R31-'переходы'!C29)^2 -> 27.04 | C21: =('переходы'!$R31-'переходы'!F29)^2 -> 246.49 | D21: =('переходы'!$R31)^2 -> 146842.24 | E21: =('переходы'!$R31)^2 -> 146842.24 | F21: =('переходы'!$R31)^2 -> 146842.24 | G21: 2e-08 | I21: =I47 -> HOMO -> LUMO+3 | J21: =B27 -> 0.0074651006 | K21: =C27 -> 0.021540016 | L21: =D27 -> 0.066732387 | M21: =E27 -> 0.096018155 | N21: =F27 -> 0.0030019814
A22: 54 -> 55 | B22: =(1240/'переходы'!$R32-1240/'переходы'!C29)^2 -> 0.026371613 | C22: =(1240/'переходы'!$R32-1240/'переходы'!F29)^2 -> 0.00036753893 | D22: =(1240/'переходы'!$R32-1240/'переходы'!I29)^2 -> 0.050380388 | E22: =(1240/'переходы'!$R32-1240/'переходы'!L29)^2 -> 0.14434709 | F22: =(1240/'переходы'!$R32-1240 /'переходы'!O29)^2 -> 0.18500789 | G22: 0.44451222 | I22: =I48 -> HOMO -> LUMO+4 | J22: =B28 -> 0.001721998 | K22: =C28 -> 0.0036151024 | L22: =D28 -> 0.093986531 | M22: =E28 -> — | N22: =F28 -> 0.012302753
A23: 54 -> 56 | B23: =(1240/'переходы'!$R33-1240/'переходы'!C31)^2 -> 0.0073765911 | C23: =(1240/'переходы'!$R33-1240/'переходы'!F30)^2 -> 0.004519844 | D23: =(1240/'переходы'!$R33-1240/'переходы'!I30)^2 -> 0.057761477 | E23: =(1240/'переходы'!$R33-1240/'переходы'!L30)^2 -> 0.24417662 | F23: =(1240/'переходы'!$R33-1240/'переходы'!O31)^2 -> 0.21121426 | G23: 0.043827317 | I23: Cu3[SCH3]2
A24: 54 -> 58 | B24: =('переходы'!$R34)^2 -> 115872.16 | C24: =('переходы'!$R34)^2 -> 115872.16 | D24: =('переходы'!$R34)^2 -> 115872.16 | E24: =('переходы'!$R34)^2 -> 115872.16 | F24: =('переходы'!$R34)^2 -> 115872.16 | G24: 1.75e-07 | I24: =I50 -> HOMO -> LUMO | J24: =B34 -> 0.00082301636 | K24: =C34 -> 0.10232037 | L24: =D34 -> 0.00020404352 | M24: =E34 -> 0.066485612 | N24: =F34 -> 0.20302446
A25: 54 -> 57 | B25: =(1240/'переходы'!$R35-1240/'переходы'!C31)^2 -> 0.0033352305 | C25: =(1240/'переходы'!$R35-1240/'переходы'!F31)^2 -> 0.00040128171 | D25: =(1240/'переходы'!$R35-1240/'переходы'!I31)^2 -> 0.096310903 | E25: =(1240/'переходы'!$R35-1240/'переходы'!L31)^2 -> 0.022429377 | F25: =(1240/'переходы'!$R35-1240/'переходы'!O30)^2 -> 0.040281105 | G25: 0.30871503 | I25: Cu4[SCH3]3
A26: 54 -> 59 | B26: =('переходы'!$R36)^2 -> 82828.84 | C26: =('переходы'!$R36)^2 -> 82828.84 | D26: =('переходы'!$R36)^2 -> 82828.84 | E26: =('переходы'!$R36)^2 -> 82828.84 | F26: =('переходы'!$R36)^2 -> 82828.84 | G26: 3.67e-07 | I26: =I52 -> HOMO -> LUMO | J26: =B42 -> 0.011095257 | K26: =C42 -> 0.0027029113 | L26: =D42 -> 0.096738301 | M26: =E42 -> 0.12311517 | N26: =F42 -> 0.026997937
A27: 54 -> 58 | B27: =(1240/'переходы'!$R37-1240/'переходы'!C32)^2 -> 0.0074651006 | C27: =(1240/'переходы'!$R37-1240/'переходы'!F34)^2 -> 0.021540016 | D27: =(1240/'переходы'!$R37-1240/'переходы'!I32)^2 -> 0.066732387 | E27: =(1240/'переходы'!$R37-1240/'переходы'!L36)^2 -> 0.096018155 | F27: =(1240/'переходы'!$R37-1240/'переходы'!O32)^2 -> 0.0030019814 | G27: 0.028367392 | I27: =I53 -> HOMO -> LUMO+1 | J27: =B44 -> 0.014812676 | K27: =C44 -> 0.0037583067 | L27: =D44 -> 0.025426488 | M27: =E44 -> 0.00031320012 | N27: =F44 -> 0.0035915367
A28: 54 -> 59 | B28: =(1240/'переходы'!$R38-1240/'переходы'!C35)^2 -> 0.001721998 | C28: =(1240/'переходы'!$R38-1240/'переходы'!F40)^2 -> 0.0036151024 | D28: =(1240/'переходы'!$R38-1240/'переходы'!I35)^2 -> 0.093986531 | E28: — | F28: =(1240/'переходы'!$R38-1240/'переходы'!O39)^2 -> 0.012302753 | G28: 0.006322222 | I28: =I54 -> HOMO -> LUMO+2 | J28: =B45 -> 0.0051710315 | K28: =C45 -> 0.065992445 | L28: =D45 -> 0.17580171 | M28: =E45 -> 0.022317458 | N28: =F45 -> 0.50829513
I29: =I55 -> HOMO -> LUMO+5 | J29: =B46 -> 0.034385247 | K29: =C46 -> 0.10557597 | L29: =D46 -> 0.0053091485 | M29: =E46 -> 0.023350583 | N29: =F46 -> 0.0046795882
I30: Cu5[SCH3]4
A31: Cu3 | I31: =I57 -> HOMO -> LUMO | J31: =B53 -> 0.094105697 | K31: =C53 -> 0.029546708 | L31: =D53 -> 0.071580861 | M31: =E53 -> 0.098097039 | N31: =F53 -> 0.014046588
A32: Переход | B32: BHandHLYP | C32: CAM-B3LYP | D32: M06-2X | E32: PBE0 | F32: wB97X | G32: CCSD: f_osc | I32: =I58 -> HOMO -> LUMO+1 | J32: =B55 -> 1.6059278 | K32: =C55 -> 0.35399809 | L32: =D55 -> 0.64187819 | M32: =E55 -> 0.7476408 | N32: =F55 -> 0.22002459
A33: 64 -> 69 | B33: =('переходы'!$R46)^2 -> 196603.56 | C33: =('переходы'!$R46)^2 -> 196603.56 | D33: =('переходы'!$R46)^2 -> 196603.56 | E33: =('переходы'!$R46)^2 -> 196603.56 | F33: =('переходы'!$R46)^2 -> 196603.56 | G33: 0.002705358 | I33: =I59 -> HOMO -> LUMO+4 | J33: =B56 -> 0.14345881 | K33: =C56 -> 0.012624189 | L33: =D56 -> 0.16371435 | M33: =E56 -> 0.29666837 | N33: =F56 -> —
A34: 68 -> 69 | B34: =(1240/'переходы'!$R47-1240/'переходы'!C46)^2 -> 0.00082301636 | C34: =(1240/'переходы'!$R47-1240/'переходы'!F46)^2 -> 0.10232037 | D34: =(1240/'переходы'!$R47-1240/'переходы'!I46)^2 -> 0.00020404352 | E34: =(1240/'переходы'!$R47-1240/'переходы'!L46)^2 -> 0.066485612 | F34: =(1240/'переходы'!$R47-1240/'переходы'!O46)^2 -> 0.20302446 | G34: 0.50187388 | I34: =I60 -> HOMO -> LUMO+5 | J34: =B57 -> 0.027659719 | K34: =C57 -> — | L34: =D57 -> 0.09285666 | M34: =E57 -> — | N34: =F57 -> 0.00025522412
A35: 64 -> 71 64 -> 73 66 -> 69 | B35: =('переходы'!$R48)^2 -> 76618.24 | C35: =('переходы'!$R48)^2 -> 76618.24 | D35: =('переходы'!$R48)^2 -> 76618.24 | E35: =('переходы'!$R48)^2 -> 76618.24 | F35: =('переходы'!$R48)^2 -> 76618.24 | G35: 0.009291543
A36: 64 -> 71; 64 -> 73; 66 -> 69 | B36: =('переходы'!$R49)^2 -> 59976.01 | C36: =('переходы'!$R49)^2 -> 59976.01 | D36: =('переходы'!$R49)^2 -> 59976.01 | E36: =('переходы'!$R49)^2 -> 59976.01 | F36: =('переходы'!$R49)^2 -> 59976.01 | G36: 0.092370818 | I36: Энергии соответствующих переходов для DFT функционалов и CCSD в эВ
A37: 60 -> 69 68 -> 72 | B37: =('переходы'!$R50)^2 -> 53314.81 | C37: =('переходы'!$R50)^2 -> 53314.81 | D37: =('переходы'!$R50)^2 -> 53314.81 | E37: =('переходы'!$R50)^2 -> 53314.81 | F37: =('переходы'!$R50)^2 -> 53314.81 | G37: 0.020176819 | I37: переход | J37: BHandHLYP | K37: CAM-B3LYP | L37: M06-2X | M37: PBE0 | N37: wB97X | O37: CCSD
I38: Cu[SCH3]2
I39: HOMO -> LUMO | J39: =1240/'переходы'!C4 -> 4.7238095 | K39: =1240/'переходы'!F4 -> 4.5271997 | L39: =1240/'переходы'!I4 -> 4.5672192 | M39: =1240/'переходы'!L4 -> 4.277337 | N39: =1240/'переходы'!O4 -> 4.9011858 | O39: =1240/'переходы'!$R7 -> 4.4620367
A40: Cu4 | I40: HOMO-1 -> LUMO | J40: =1240/'переходы'!C5 -> 4.785797 | K40: =1240/'переходы'!F5 -> 4.595997 | L40: =1240/'переходы'!I5 -> 4.6337818 | M40: =1240/'переходы'!L5 -> 4.3600563 | N40: =1240/'переходы'!O5 -> 4.9639712 | O40: =1240/'переходы'!$R8 -> 4.5421245
...
